2024-08-30 18:55:28,390 - ERROR - Failed to loaded connection config from connection.yaml: [Errno 2] No such file or directory: 'connection.yaml'
Traceback (most recent call last):
  File "/Users/mac/my_project/DummyGenerator/utils/db_setup.py", line 11, in load_yaml
    with open(file_path, 'r') as file:
         ^^^^^^^^^^^^^^^^^^^^
FileNotFoundError: [Errno 2] No such file or directory: 'connection.yaml'
2024-08-30 18:55:28,391 - ERROR - An unexpected error occurred: [Errno 2] No such file or directory: 'connection.yaml'
Traceback (most recent call last):
  File "/Users/mac/my_project/DummyGenerator/main.py", line 84, in main
    connection_config = load_connection_config('connection.yaml')
                        ^^^^^^^^^^^^^^^^^^^^^^^^^^^^^^^^^^^^^^^^^
  File "/Users/mac/my_project/DummyGenerator/utils/db_setup.py", line 21, in load_connection_config
    return load_yaml(file_path, "Loaded connection config")
           ^^^^^^^^^^^^^^^^^^^^^^^^^^^^^^^^^^^^^^^^^^^^^^^^
  File "/Users/mac/my_project/DummyGenerator/utils/db_setup.py", line 11, in load_yaml
    with open(file_path, 'r') as file:
         ^^^^^^^^^^^^^^^^^^^^
FileNotFoundError: [Errno 2] No such file or directory: 'connection.yaml'
2024-09-04 15:50:10,240 - ERROR - Failed to loaded connection config from connection.yaml: [Errno 2] No such file or directory: 'connection.yaml'
Traceback (most recent call last):
  File "/Users/mac/my_project/DummyGenerator/utils/db_setup.py", line 11, in load_yaml
    with open(file_path, 'r') as file:
         ^^^^^^^^^^^^^^^^^^^^
FileNotFoundError: [Errno 2] No such file or directory: 'connection.yaml'
2024-09-04 15:50:10,241 - ERROR - An unexpected error occurred: [Errno 2] No such file or directory: 'connection.yaml'
Traceback (most recent call last):
  File "/Users/mac/my_project/DummyGenerator/main copy 3.py", line 134, in main
    connection_config = load_connection_config('connection.yaml')
                        ^^^^^^^^^^^^^^^^^^^^^^^^^^^^^^^^^^^^^^^^^
  File "/Users/mac/my_project/DummyGenerator/utils/db_setup.py", line 21, in load_connection_config
    return load_yaml(file_path, "Loaded connection config")
           ^^^^^^^^^^^^^^^^^^^^^^^^^^^^^^^^^^^^^^^^^^^^^^^^
  File "/Users/mac/my_project/DummyGenerator/utils/db_setup.py", line 11, in load_yaml
    with open(file_path, 'r') as file:
         ^^^^^^^^^^^^^^^^^^^^
FileNotFoundError: [Errno 2] No such file or directory: 'connection.yaml'
2024-09-04 15:51:02,474 - ERROR - Failed to loaded connection config from connection.yaml: [Errno 2] No such file or directory: 'connection.yaml'
Traceback (most recent call last):
  File "/Users/mac/my_project/DummyGenerator/utils/db_setup.py", line 11, in load_yaml
    with open(file_path, 'r') as file:
         ^^^^^^^^^^^^^^^^^^^^
FileNotFoundError: [Errno 2] No such file or directory: 'connection.yaml'
2024-09-04 15:51:02,474 - ERROR - An unexpected error occurred: [Errno 2] No such file or directory: 'connection.yaml'
Traceback (most recent call last):
  File "/Users/mac/my_project/DummyGenerator/main copy 3.py", line 134, in main
    connection_config = load_connection_config('connection.yaml')
                        ^^^^^^^^^^^^^^^^^^^^^^^^^^^^^^^^^^^^^^^^^
  File "/Users/mac/my_project/DummyGenerator/utils/db_setup.py", line 21, in load_connection_config
    return load_yaml(file_path, "Loaded connection config")
           ^^^^^^^^^^^^^^^^^^^^^^^^^^^^^^^^^^^^^^^^^^^^^^^^
  File "/Users/mac/my_project/DummyGenerator/utils/db_setup.py", line 11, in load_yaml
    with open(file_path, 'r') as file:
         ^^^^^^^^^^^^^^^^^^^^
FileNotFoundError: [Errno 2] No such file or directory: 'connection.yaml'
2024-09-04 15:51:22,968 - ERROR - Failed to loaded connection config from ./connection.yaml: [Errno 2] No such file or directory: './connection.yaml'
Traceback (most recent call last):
  File "/Users/mac/my_project/DummyGenerator/utils/db_setup.py", line 11, in load_yaml
    with open(file_path, 'r') as file:
         ^^^^^^^^^^^^^^^^^^^^
FileNotFoundError: [Errno 2] No such file or directory: './connection.yaml'
2024-09-04 15:51:22,968 - ERROR - An unexpected error occurred: [Errno 2] No such file or directory: './connection.yaml'
Traceback (most recent call last):
  File "/Users/mac/my_project/DummyGenerator/main copy 3.py", line 134, in main
    connection_config = load_connection_config('./connection.yaml')
                        ^^^^^^^^^^^^^^^^^^^^^^^^^^^^^^^^^^^^^^^^^^^
  File "/Users/mac/my_project/DummyGenerator/utils/db_setup.py", line 21, in load_connection_config
    return load_yaml(file_path, "Loaded connection config")
           ^^^^^^^^^^^^^^^^^^^^^^^^^^^^^^^^^^^^^^^^^^^^^^^^
  File "/Users/mac/my_project/DummyGenerator/utils/db_setup.py", line 11, in load_yaml
    with open(file_path, 'r') as file:
         ^^^^^^^^^^^^^^^^^^^^
FileNotFoundError: [Errno 2] No such file or directory: './connection.yaml'
2024-09-04 15:57:46,485 - INFO - Loaded connection config from /Users/mac/my_project/DummyGenerator/connection.yaml
2024-09-04 15:57:51,073 - INFO - Created database engine with connection string: mysql+pymysql://root:208300@localhost:3306/
2024-09-04 15:57:53,745 - ERROR - An unexpected error occurred: cannot access local variable 'db_name' where it is not associated with a value
Traceback (most recent call last):
  File "/Users/mac/my_project/DummyGenerator/main copy 3.py", line 166, in main
    print(f"Schemas in database {db_name}:", schemas)
                                 ^^^^^^^
UnboundLocalError: cannot access local variable 'db_name' where it is not associated with a value
2024-09-04 16:04:08,714 - ERROR - Failed to loaded connection config from connection.yaml: [Errno 2] No such file or directory: 'connection.yaml'
Traceback (most recent call last):
  File "/Users/mac/my_project/DummyGenerator/utils/db_setup.py", line 11, in load_yaml
    with open(file_path, 'r') as file:
         ^^^^^^^^^^^^^^^^^^^^
FileNotFoundError: [Errno 2] No such file or directory: 'connection.yaml'
2024-09-04 16:04:08,715 - ERROR - An unexpected error occurred: [Errno 2] No such file or directory: 'connection.yaml'
Traceback (most recent call last):
  File "/Users/mac/my_project/DummyGenerator/main copy.py", line 82, in main
    connection_config = load_connection_config('connection.yaml')
                        ^^^^^^^^^^^^^^^^^^^^^^^^^^^^^^^^^^^^^^^^^
  File "/Users/mac/my_project/DummyGenerator/utils/db_setup.py", line 21, in load_connection_config
    return load_yaml(file_path, "Loaded connection config")
           ^^^^^^^^^^^^^^^^^^^^^^^^^^^^^^^^^^^^^^^^^^^^^^^^
  File "/Users/mac/my_project/DummyGenerator/utils/db_setup.py", line 11, in load_yaml
    with open(file_path, 'r') as file:
         ^^^^^^^^^^^^^^^^^^^^
FileNotFoundError: [Errno 2] No such file or directory: 'connection.yaml'
2024-09-04 16:10:26,985 - INFO - Loaded connection config from /Users/mac/my_project/DummyGenerator/connection.yaml
2024-09-04 16:10:30,677 - INFO - Created database engine with connection string: mysql+pymysql://root:208300@localhost:3306/
2024-09-04 16:14:29,762 - INFO - Loaded connection config from /Users/mac/my_project/DummyGenerator/connection.yaml
2024-09-04 16:14:31,744 - INFO - Created database engine with connection string: mysql+pymysql://root:1@localhost:3306/
2024-09-04 16:14:33,145 - ERROR - An unexpected error occurred: (pymysql.err.OperationalError) (1045, "Access denied for user 'root'@'localhost' (using password: YES)")
(Background on this error at: https://sqlalche.me/e/20/e3q8)
Traceback (most recent call last):
  File "/Users/mac/Library/Caches/pypoetry/virtualenvs/dummy-ueek8zWF-py3.12/lib/python3.12/site-packages/sqlalchemy/engine/base.py", line 146, in __init__
    self._dbapi_connection = engine.raw_connection()
                             ^^^^^^^^^^^^^^^^^^^^^^^
  File "/Users/mac/Library/Caches/pypoetry/virtualenvs/dummy-ueek8zWF-py3.12/lib/python3.12/site-packages/sqlalchemy/engine/base.py", line 3302, in raw_connection
    return self.pool.connect()
           ^^^^^^^^^^^^^^^^^^^
  File "/Users/mac/Library/Caches/pypoetry/virtualenvs/dummy-ueek8zWF-py3.12/lib/python3.12/site-packages/sqlalchemy/pool/base.py", line 449, in connect
    return _ConnectionFairy._checkout(self)
           ^^^^^^^^^^^^^^^^^^^^^^^^^^^^^^^^
  File "/Users/mac/Library/Caches/pypoetry/virtualenvs/dummy-ueek8zWF-py3.12/lib/python3.12/site-packages/sqlalchemy/pool/base.py", line 1263, in _checkout
    fairy = _ConnectionRecord.checkout(pool)
            ^^^^^^^^^^^^^^^^^^^^^^^^^^^^^^^^
  File "/Users/mac/Library/Caches/pypoetry/virtualenvs/dummy-ueek8zWF-py3.12/lib/python3.12/site-packages/sqlalchemy/pool/base.py", line 712, in checkout
    rec = pool._do_get()
          ^^^^^^^^^^^^^^
  File "/Users/mac/Library/Caches/pypoetry/virtualenvs/dummy-ueek8zWF-py3.12/lib/python3.12/site-packages/sqlalchemy/pool/impl.py", line 179, in _do_get
    with util.safe_reraise():
  File "/Users/mac/Library/Caches/pypoetry/virtualenvs/dummy-ueek8zWF-py3.12/lib/python3.12/site-packages/sqlalchemy/util/langhelpers.py", line 146, in __exit__
    raise exc_value.with_traceback(exc_tb)
  File "/Users/mac/Library/Caches/pypoetry/virtualenvs/dummy-ueek8zWF-py3.12/lib/python3.12/site-packages/sqlalchemy/pool/impl.py", line 177, in _do_get
    return self._create_connection()
           ^^^^^^^^^^^^^^^^^^^^^^^^^
  File "/Users/mac/Library/Caches/pypoetry/virtualenvs/dummy-ueek8zWF-py3.12/lib/python3.12/site-packages/sqlalchemy/pool/base.py", line 390, in _create_connection
    return _ConnectionRecord(self)
           ^^^^^^^^^^^^^^^^^^^^^^^
  File "/Users/mac/Library/Caches/pypoetry/virtualenvs/dummy-ueek8zWF-py3.12/lib/python3.12/site-packages/sqlalchemy/pool/base.py", line 674, in __init__
    self.__connect()
  File "/Users/mac/Library/Caches/pypoetry/virtualenvs/dummy-ueek8zWF-py3.12/lib/python3.12/site-packages/sqlalchemy/pool/base.py", line 900, in __connect
    with util.safe_reraise():
  File "/Users/mac/Library/Caches/pypoetry/virtualenvs/dummy-ueek8zWF-py3.12/lib/python3.12/site-packages/sqlalchemy/util/langhelpers.py", line 146, in __exit__
    raise exc_value.with_traceback(exc_tb)
  File "/Users/mac/Library/Caches/pypoetry/virtualenvs/dummy-ueek8zWF-py3.12/lib/python3.12/site-packages/sqlalchemy/pool/base.py", line 896, in __connect
    self.dbapi_connection = connection = pool._invoke_creator(self)
                                         ^^^^^^^^^^^^^^^^^^^^^^^^^^
  File "/Users/mac/Library/Caches/pypoetry/virtualenvs/dummy-ueek8zWF-py3.12/lib/python3.12/site-packages/sqlalchemy/engine/create.py", line 643, in connect
    return dialect.connect(*cargs, **cparams)
           ^^^^^^^^^^^^^^^^^^^^^^^^^^^^^^^^^^
  File "/Users/mac/Library/Caches/pypoetry/virtualenvs/dummy-ueek8zWF-py3.12/lib/python3.12/site-packages/sqlalchemy/engine/default.py", line 621, in connect
    return self.loaded_dbapi.connect(*cargs, **cparams)
           ^^^^^^^^^^^^^^^^^^^^^^^^^^^^^^^^^^^^^^^^^^^^
  File "/Users/mac/Library/Caches/pypoetry/virtualenvs/dummy-ueek8zWF-py3.12/lib/python3.12/site-packages/pymysql/connections.py", line 361, in __init__
    self.connect()
  File "/Users/mac/Library/Caches/pypoetry/virtualenvs/dummy-ueek8zWF-py3.12/lib/python3.12/site-packages/pymysql/connections.py", line 669, in connect
    self._request_authentication()
  File "/Users/mac/Library/Caches/pypoetry/virtualenvs/dummy-ueek8zWF-py3.12/lib/python3.12/site-packages/pymysql/connections.py", line 979, in _request_authentication
    auth_packet = _auth.caching_sha2_password_auth(self, auth_packet)
                  ^^^^^^^^^^^^^^^^^^^^^^^^^^^^^^^^^^^^^^^^^^^^^^^^^^^
  File "/Users/mac/Library/Caches/pypoetry/virtualenvs/dummy-ueek8zWF-py3.12/lib/python3.12/site-packages/pymysql/_auth.py", line 268, in caching_sha2_password_auth
    pkt = _roundtrip(conn, data)
          ^^^^^^^^^^^^^^^^^^^^^^
  File "/Users/mac/Library/Caches/pypoetry/virtualenvs/dummy-ueek8zWF-py3.12/lib/python3.12/site-packages/pymysql/_auth.py", line 121, in _roundtrip
    pkt = conn._read_packet()
          ^^^^^^^^^^^^^^^^^^^
  File "/Users/mac/Library/Caches/pypoetry/virtualenvs/dummy-ueek8zWF-py3.12/lib/python3.12/site-packages/pymysql/connections.py", line 775, in _read_packet
    packet.raise_for_error()
  File "/Users/mac/Library/Caches/pypoetry/virtualenvs/dummy-ueek8zWF-py3.12/lib/python3.12/site-packages/pymysql/protocol.py", line 219, in raise_for_error
    err.raise_mysql_exception(self._data)
  File "/Users/mac/Library/Caches/pypoetry/virtualenvs/dummy-ueek8zWF-py3.12/lib/python3.12/site-packages/pymysql/err.py", line 150, in raise_mysql_exception
    raise errorclass(errno, errval)
pymysql.err.OperationalError: (1045, "Access denied for user 'root'@'localhost' (using password: YES)")

The above exception was the direct cause of the following exception:

Traceback (most recent call last):
  File "/Users/mac/my_project/DummyGenerator/main copy 3.py", line 165, in main
    schemas = get_schemas(engine)
              ^^^^^^^^^^^^^^^^^^^
  File "/Users/mac/my_project/DummyGenerator/main copy 3.py", line 83, in get_schemas
    inspector = reflection.Inspector.from_engine(engine)
                ^^^^^^^^^^^^^^^^^^^^^^^^^^^^^^^^^^^^^^^^
  File "<string>", line 2, in from_engine
  File "/Users/mac/Library/Caches/pypoetry/virtualenvs/dummy-ueek8zWF-py3.12/lib/python3.12/site-packages/sqlalchemy/util/deprecations.py", line 386, in warned
    return fn(*args, **kwargs)  # type: ignore[no-any-return]
           ^^^^^^^^^^^^^^^^^^^
  File "/Users/mac/Library/Caches/pypoetry/virtualenvs/dummy-ueek8zWF-py3.12/lib/python3.12/site-packages/sqlalchemy/engine/reflection.py", line 299, in from_engine
    return cls._construct(cls._init_legacy, bind)
           ^^^^^^^^^^^^^^^^^^^^^^^^^^^^^^^^^^^^^^
  File "/Users/mac/Library/Caches/pypoetry/virtualenvs/dummy-ueek8zWF-py3.12/lib/python3.12/site-packages/sqlalchemy/engine/reflection.py", line 236, in _construct
    init(self, bind)
  File "/Users/mac/Library/Caches/pypoetry/virtualenvs/dummy-ueek8zWF-py3.12/lib/python3.12/site-packages/sqlalchemy/engine/reflection.py", line 243, in _init_legacy
    self._init_engine(bind)
  File "/Users/mac/Library/Caches/pypoetry/virtualenvs/dummy-ueek8zWF-py3.12/lib/python3.12/site-packages/sqlalchemy/engine/reflection.py", line 247, in _init_engine
    engine.connect().close()
    ^^^^^^^^^^^^^^^^
  File "/Users/mac/Library/Caches/pypoetry/virtualenvs/dummy-ueek8zWF-py3.12/lib/python3.12/site-packages/sqlalchemy/engine/base.py", line 3278, in connect
    return self._connection_cls(self)
           ^^^^^^^^^^^^^^^^^^^^^^^^^^
  File "/Users/mac/Library/Caches/pypoetry/virtualenvs/dummy-ueek8zWF-py3.12/lib/python3.12/site-packages/sqlalchemy/engine/base.py", line 148, in __init__
    Connection._handle_dbapi_exception_noconnection(
  File "/Users/mac/Library/Caches/pypoetry/virtualenvs/dummy-ueek8zWF-py3.12/lib/python3.12/site-packages/sqlalchemy/engine/base.py", line 2442, in _handle_dbapi_exception_noconnection
    raise sqlalchemy_exception.with_traceback(exc_info[2]) from e
  File "/Users/mac/Library/Caches/pypoetry/virtualenvs/dummy-ueek8zWF-py3.12/lib/python3.12/site-packages/sqlalchemy/engine/base.py", line 146, in __init__
    self._dbapi_connection = engine.raw_connection()
                             ^^^^^^^^^^^^^^^^^^^^^^^
  File "/Users/mac/Library/Caches/pypoetry/virtualenvs/dummy-ueek8zWF-py3.12/lib/python3.12/site-packages/sqlalchemy/engine/base.py", line 3302, in raw_connection
    return self.pool.connect()
           ^^^^^^^^^^^^^^^^^^^
  File "/Users/mac/Library/Caches/pypoetry/virtualenvs/dummy-ueek8zWF-py3.12/lib/python3.12/site-packages/sqlalchemy/pool/base.py", line 449, in connect
    return _ConnectionFairy._checkout(self)
           ^^^^^^^^^^^^^^^^^^^^^^^^^^^^^^^^
  File "/Users/mac/Library/Caches/pypoetry/virtualenvs/dummy-ueek8zWF-py3.12/lib/python3.12/site-packages/sqlalchemy/pool/base.py", line 1263, in _checkout
    fairy = _ConnectionRecord.checkout(pool)
            ^^^^^^^^^^^^^^^^^^^^^^^^^^^^^^^^
  File "/Users/mac/Library/Caches/pypoetry/virtualenvs/dummy-ueek8zWF-py3.12/lib/python3.12/site-packages/sqlalchemy/pool/base.py", line 712, in checkout
    rec = pool._do_get()
          ^^^^^^^^^^^^^^
  File "/Users/mac/Library/Caches/pypoetry/virtualenvs/dummy-ueek8zWF-py3.12/lib/python3.12/site-packages/sqlalchemy/pool/impl.py", line 179, in _do_get
    with util.safe_reraise():
  File "/Users/mac/Library/Caches/pypoetry/virtualenvs/dummy-ueek8zWF-py3.12/lib/python3.12/site-packages/sqlalchemy/util/langhelpers.py", line 146, in __exit__
    raise exc_value.with_traceback(exc_tb)
  File "/Users/mac/Library/Caches/pypoetry/virtualenvs/dummy-ueek8zWF-py3.12/lib/python3.12/site-packages/sqlalchemy/pool/impl.py", line 177, in _do_get
    return self._create_connection()
           ^^^^^^^^^^^^^^^^^^^^^^^^^
  File "/Users/mac/Library/Caches/pypoetry/virtualenvs/dummy-ueek8zWF-py3.12/lib/python3.12/site-packages/sqlalchemy/pool/base.py", line 390, in _create_connection
    return _ConnectionRecord(self)
           ^^^^^^^^^^^^^^^^^^^^^^^
  File "/Users/mac/Library/Caches/pypoetry/virtualenvs/dummy-ueek8zWF-py3.12/lib/python3.12/site-packages/sqlalchemy/pool/base.py", line 674, in __init__
    self.__connect()
  File "/Users/mac/Library/Caches/pypoetry/virtualenvs/dummy-ueek8zWF-py3.12/lib/python3.12/site-packages/sqlalchemy/pool/base.py", line 900, in __connect
    with util.safe_reraise():
  File "/Users/mac/Library/Caches/pypoetry/virtualenvs/dummy-ueek8zWF-py3.12/lib/python3.12/site-packages/sqlalchemy/util/langhelpers.py", line 146, in __exit__
    raise exc_value.with_traceback(exc_tb)
  File "/Users/mac/Library/Caches/pypoetry/virtualenvs/dummy-ueek8zWF-py3.12/lib/python3.12/site-packages/sqlalchemy/pool/base.py", line 896, in __connect
    self.dbapi_connection = connection = pool._invoke_creator(self)
                                         ^^^^^^^^^^^^^^^^^^^^^^^^^^
  File "/Users/mac/Library/Caches/pypoetry/virtualenvs/dummy-ueek8zWF-py3.12/lib/python3.12/site-packages/sqlalchemy/engine/create.py", line 643, in connect
    return dialect.connect(*cargs, **cparams)
           ^^^^^^^^^^^^^^^^^^^^^^^^^^^^^^^^^^
  File "/Users/mac/Library/Caches/pypoetry/virtualenvs/dummy-ueek8zWF-py3.12/lib/python3.12/site-packages/sqlalchemy/engine/default.py", line 621, in connect
    return self.loaded_dbapi.connect(*cargs, **cparams)
           ^^^^^^^^^^^^^^^^^^^^^^^^^^^^^^^^^^^^^^^^^^^^
  File "/Users/mac/Library/Caches/pypoetry/virtualenvs/dummy-ueek8zWF-py3.12/lib/python3.12/site-packages/pymysql/connections.py", line 361, in __init__
    self.connect()
  File "/Users/mac/Library/Caches/pypoetry/virtualenvs/dummy-ueek8zWF-py3.12/lib/python3.12/site-packages/pymysql/connections.py", line 669, in connect
    self._request_authentication()
  File "/Users/mac/Library/Caches/pypoetry/virtualenvs/dummy-ueek8zWF-py3.12/lib/python3.12/site-packages/pymysql/connections.py", line 979, in _request_authentication
    auth_packet = _auth.caching_sha2_password_auth(self, auth_packet)
                  ^^^^^^^^^^^^^^^^^^^^^^^^^^^^^^^^^^^^^^^^^^^^^^^^^^^
  File "/Users/mac/Library/Caches/pypoetry/virtualenvs/dummy-ueek8zWF-py3.12/lib/python3.12/site-packages/pymysql/_auth.py", line 268, in caching_sha2_password_auth
    pkt = _roundtrip(conn, data)
          ^^^^^^^^^^^^^^^^^^^^^^
  File "/Users/mac/Library/Caches/pypoetry/virtualenvs/dummy-ueek8zWF-py3.12/lib/python3.12/site-packages/pymysql/_auth.py", line 121, in _roundtrip
    pkt = conn._read_packet()
          ^^^^^^^^^^^^^^^^^^^
  File "/Users/mac/Library/Caches/pypoetry/virtualenvs/dummy-ueek8zWF-py3.12/lib/python3.12/site-packages/pymysql/connections.py", line 775, in _read_packet
    packet.raise_for_error()
  File "/Users/mac/Library/Caches/pypoetry/virtualenvs/dummy-ueek8zWF-py3.12/lib/python3.12/site-packages/pymysql/protocol.py", line 219, in raise_for_error
    err.raise_mysql_exception(self._data)
  File "/Users/mac/Library/Caches/pypoetry/virtualenvs/dummy-ueek8zWF-py3.12/lib/python3.12/site-packages/pymysql/err.py", line 150, in raise_mysql_exception
    raise errorclass(errno, errval)
sqlalchemy.exc.OperationalError: (pymysql.err.OperationalError) (1045, "Access denied for user 'root'@'localhost' (using password: YES)")
(Background on this error at: https://sqlalche.me/e/20/e3q8)
2024-09-04 16:14:36,153 - INFO - Loaded connection config from /Users/mac/my_project/DummyGenerator/connection.yaml
2024-09-04 16:14:39,162 - INFO - Created database engine with connection string: mysql+pymysql://root:208300@localhost:3306/
2024-09-04 16:17:59,045 - INFO - Loaded connection config from /Users/mac/my_project/DummyGenerator/connection.yaml
2024-09-04 16:18:02,264 - ERROR - An error occurred while creating the database engine: Missing required connection parameters.
Traceback (most recent call last):
  File "/Users/mac/my_project/DummyGenerator/utils/db_setup.py", line 123, in create_engine_connection
    raise ValueError("Missing required connection parameters.")
ValueError: Missing required connection parameters.
2024-09-04 16:18:02,265 - ERROR - An error occurred while setting up the database: Missing required connection parameters.
Traceback (most recent call last):
  File "/Users/mac/my_project/DummyGenerator/utils/db_setup.py", line 140, in setup_database
    engine = create_engine_connection(connection_config, database_name)
             ^^^^^^^^^^^^^^^^^^^^^^^^^^^^^^^^^^^^^^^^^^^^^^^^^^^^^^^^^^
  File "/Users/mac/my_project/DummyGenerator/utils/db_setup.py", line 123, in create_engine_connection
    raise ValueError("Missing required connection parameters.")
ValueError: Missing required connection parameters.
2024-09-04 16:18:02,265 - ERROR - Failed to connect to the server server1: Missing required connection parameters.
2024-09-04 16:28:16,726 - INFO - Loaded connection config from /Users/mac/my_project/DummyGenerator/connection.yaml
2024-09-04 16:28:34,929 - ERROR - An error occurred while creating the database engine: Missing required connection parameters.
Traceback (most recent call last):
  File "/Users/mac/my_project/DummyGenerator/utils/db_setup.py", line 123, in create_engine_connection
    raise ValueError("Missing required connection parameters.")
ValueError: Missing required connection parameters.
2024-09-04 16:28:34,930 - ERROR - An error occurred while setting up the database: Missing required connection parameters.
Traceback (most recent call last):
  File "/Users/mac/my_project/DummyGenerator/utils/db_setup.py", line 140, in setup_database
    engine = create_engine_connection(connection_config, database_name)
             ^^^^^^^^^^^^^^^^^^^^^^^^^^^^^^^^^^^^^^^^^^^^^^^^^^^^^^^^^^
  File "/Users/mac/my_project/DummyGenerator/utils/db_setup.py", line 123, in create_engine_connection
    raise ValueError("Missing required connection parameters.")
ValueError: Missing required connection parameters.
2024-09-04 16:28:34,930 - ERROR - Failed to connect to the server server1: Missing required connection parameters.
2024-09-04 16:38:02,619 - INFO - Loaded connection config from /Users/mac/my_project/DummyGenerator/connection.yaml
2024-09-04 16:38:07,482 - INFO - Created database engine with connection string: mysql+pymysql://root:208300@localhost:3306/
2024-09-04 16:40:56,446 - ERROR - An unexpected error occurred: cannot access local variable 'db_name' where it is not associated with a value
Traceback (most recent call last):
  File "/Users/mac/my_project/DummyGenerator/main copy 3.py", line 208, in main
UnboundLocalError: cannot access local variable 'db_name' where it is not associated with a value
