2024-09-04 15:00:36,098 - ERROR - Failed to insert data into airport: (pymysql.err.IntegrityError) (1062, "Duplicate entry 'WVht' for key 'airport.icao_unq'")
[SQL: INSERT INTO airport (airport_id, iata, icao, name) VALUES (%(airport_id)s, %(iata)s, %(icao)s, %(name)s)]
[parameters: {'airport_id': None, 'iata': 'lox', 'icao': 'WVht', 'name': 'MxlXDooscRSHtVUzLLGwOYBmaeHKGxdnSnNMpuIzxehUgfBOKo'}]
(Background on this error at: https://sqlalche.me/e/20/gkpj)
Traceback (most recent call last):
  File "/Users/mac/Library/Caches/pypoetry/virtualenvs/dummy-ueek8zWF-py3.12/lib/python3.12/site-packages/sqlalchemy/engine/base.py", line 1967, in _exec_single_context
    self.dialect.do_execute(
  File "/Users/mac/Library/Caches/pypoetry/virtualenvs/dummy-ueek8zWF-py3.12/lib/python3.12/site-packages/sqlalchemy/engine/default.py", line 941, in do_execute
    cursor.execute(statement, parameters)
  File "/Users/mac/Library/Caches/pypoetry/virtualenvs/dummy-ueek8zWF-py3.12/lib/python3.12/site-packages/pymysql/cursors.py", line 153, in execute
    result = self._query(query)
             ^^^^^^^^^^^^^^^^^^
  File "/Users/mac/Library/Caches/pypoetry/virtualenvs/dummy-ueek8zWF-py3.12/lib/python3.12/site-packages/pymysql/cursors.py", line 322, in _query
    conn.query(q)
  File "/Users/mac/Library/Caches/pypoetry/virtualenvs/dummy-ueek8zWF-py3.12/lib/python3.12/site-packages/pymysql/connections.py", line 563, in query
    self._affected_rows = self._read_query_result(unbuffered=unbuffered)
                          ^^^^^^^^^^^^^^^^^^^^^^^^^^^^^^^^^^^^^^^^^^^^^^
  File "/Users/mac/Library/Caches/pypoetry/virtualenvs/dummy-ueek8zWF-py3.12/lib/python3.12/site-packages/pymysql/connections.py", line 825, in _read_query_result
    result.read()
  File "/Users/mac/Library/Caches/pypoetry/virtualenvs/dummy-ueek8zWF-py3.12/lib/python3.12/site-packages/pymysql/connections.py", line 1199, in read
    first_packet = self.connection._read_packet()
                   ^^^^^^^^^^^^^^^^^^^^^^^^^^^^^^
  File "/Users/mac/Library/Caches/pypoetry/virtualenvs/dummy-ueek8zWF-py3.12/lib/python3.12/site-packages/pymysql/connections.py", line 775, in _read_packet
    packet.raise_for_error()
  File "/Users/mac/Library/Caches/pypoetry/virtualenvs/dummy-ueek8zWF-py3.12/lib/python3.12/site-packages/pymysql/protocol.py", line 219, in raise_for_error
    err.raise_mysql_exception(self._data)
  File "/Users/mac/Library/Caches/pypoetry/virtualenvs/dummy-ueek8zWF-py3.12/lib/python3.12/site-packages/pymysql/err.py", line 150, in raise_mysql_exception
    raise errorclass(errno, errval)
pymysql.err.IntegrityError: (1062, "Duplicate entry 'WVht' for key 'airport.icao_unq'")

The above exception was the direct cause of the following exception:

Traceback (most recent call last):
  File "/Users/mac/my_project/DummyGenerator/utils/insert_data.py", line 37, in insert_dummy_data
    conn.execute(query)
  File "/Users/mac/Library/Caches/pypoetry/virtualenvs/dummy-ueek8zWF-py3.12/lib/python3.12/site-packages/sqlalchemy/engine/base.py", line 1418, in execute
    return meth(
           ^^^^^
  File "/Users/mac/Library/Caches/pypoetry/virtualenvs/dummy-ueek8zWF-py3.12/lib/python3.12/site-packages/sqlalchemy/sql/elements.py", line 515, in _execute_on_connection
    return connection._execute_clauseelement(
           ^^^^^^^^^^^^^^^^^^^^^^^^^^^^^^^^^^
  File "/Users/mac/Library/Caches/pypoetry/virtualenvs/dummy-ueek8zWF-py3.12/lib/python3.12/site-packages/sqlalchemy/engine/base.py", line 1640, in _execute_clauseelement
    ret = self._execute_context(
          ^^^^^^^^^^^^^^^^^^^^^^
  File "/Users/mac/Library/Caches/pypoetry/virtualenvs/dummy-ueek8zWF-py3.12/lib/python3.12/site-packages/sqlalchemy/engine/base.py", line 1846, in _execute_context
    return self._exec_single_context(
           ^^^^^^^^^^^^^^^^^^^^^^^^^^
  File "/Users/mac/Library/Caches/pypoetry/virtualenvs/dummy-ueek8zWF-py3.12/lib/python3.12/site-packages/sqlalchemy/engine/base.py", line 1986, in _exec_single_context
    self._handle_dbapi_exception(
  File "/Users/mac/Library/Caches/pypoetry/virtualenvs/dummy-ueek8zWF-py3.12/lib/python3.12/site-packages/sqlalchemy/engine/base.py", line 2355, in _handle_dbapi_exception
    raise sqlalchemy_exception.with_traceback(exc_info[2]) from e
  File "/Users/mac/Library/Caches/pypoetry/virtualenvs/dummy-ueek8zWF-py3.12/lib/python3.12/site-packages/sqlalchemy/engine/base.py", line 1967, in _exec_single_context
    self.dialect.do_execute(
  File "/Users/mac/Library/Caches/pypoetry/virtualenvs/dummy-ueek8zWF-py3.12/lib/python3.12/site-packages/sqlalchemy/engine/default.py", line 941, in do_execute
    cursor.execute(statement, parameters)
  File "/Users/mac/Library/Caches/pypoetry/virtualenvs/dummy-ueek8zWF-py3.12/lib/python3.12/site-packages/pymysql/cursors.py", line 153, in execute
    result = self._query(query)
             ^^^^^^^^^^^^^^^^^^
  File "/Users/mac/Library/Caches/pypoetry/virtualenvs/dummy-ueek8zWF-py3.12/lib/python3.12/site-packages/pymysql/cursors.py", line 322, in _query
    conn.query(q)
  File "/Users/mac/Library/Caches/pypoetry/virtualenvs/dummy-ueek8zWF-py3.12/lib/python3.12/site-packages/pymysql/connections.py", line 563, in query
    self._affected_rows = self._read_query_result(unbuffered=unbuffered)
                          ^^^^^^^^^^^^^^^^^^^^^^^^^^^^^^^^^^^^^^^^^^^^^^
  File "/Users/mac/Library/Caches/pypoetry/virtualenvs/dummy-ueek8zWF-py3.12/lib/python3.12/site-packages/pymysql/connections.py", line 825, in _read_query_result
    result.read()
  File "/Users/mac/Library/Caches/pypoetry/virtualenvs/dummy-ueek8zWF-py3.12/lib/python3.12/site-packages/pymysql/connections.py", line 1199, in read
    first_packet = self.connection._read_packet()
                   ^^^^^^^^^^^^^^^^^^^^^^^^^^^^^^
  File "/Users/mac/Library/Caches/pypoetry/virtualenvs/dummy-ueek8zWF-py3.12/lib/python3.12/site-packages/pymysql/connections.py", line 775, in _read_packet
    packet.raise_for_error()
  File "/Users/mac/Library/Caches/pypoetry/virtualenvs/dummy-ueek8zWF-py3.12/lib/python3.12/site-packages/pymysql/protocol.py", line 219, in raise_for_error
    err.raise_mysql_exception(self._data)
  File "/Users/mac/Library/Caches/pypoetry/virtualenvs/dummy-ueek8zWF-py3.12/lib/python3.12/site-packages/pymysql/err.py", line 150, in raise_mysql_exception
    raise errorclass(errno, errval)
sqlalchemy.exc.IntegrityError: (pymysql.err.IntegrityError) (1062, "Duplicate entry 'WVht' for key 'airport.icao_unq'")
[SQL: INSERT INTO airport (airport_id, iata, icao, name) VALUES (%(airport_id)s, %(iata)s, %(icao)s, %(name)s)]
[parameters: {'airport_id': None, 'iata': 'lox', 'icao': 'WVht', 'name': 'MxlXDooscRSHtVUzLLGwOYBmaeHKGxdnSnNMpuIzxehUgfBOKo'}]
(Background on this error at: https://sqlalche.me/e/20/gkpj)
2024-09-04 16:45:08,827 - ERROR - Failed to insert data into airport: (pymysql.err.IntegrityError) (1062, "Duplicate entry 'kbrz' for key 'airport.icao_unq'")
[SQL: INSERT INTO airport (airport_id, iata, icao, name) VALUES (%(airport_id)s, %(iata)s, %(icao)s, %(name)s)]
[parameters: {'airport_id': None, 'iata': 'MTI', 'icao': 'kbrz', 'name': 'gDMKUgRYkAzmTiEFqjrMajVLXCAFdKSKnFryMVVKQLlYmThVxD'}]
(Background on this error at: https://sqlalche.me/e/20/gkpj)
Traceback (most recent call last):
  File "/Users/mac/Library/Caches/pypoetry/virtualenvs/dummy-ueek8zWF-py3.12/lib/python3.12/site-packages/sqlalchemy/engine/base.py", line 1967, in _exec_single_context
    self.dialect.do_execute(
  File "/Users/mac/Library/Caches/pypoetry/virtualenvs/dummy-ueek8zWF-py3.12/lib/python3.12/site-packages/sqlalchemy/engine/default.py", line 941, in do_execute
    cursor.execute(statement, parameters)
  File "/Users/mac/Library/Caches/pypoetry/virtualenvs/dummy-ueek8zWF-py3.12/lib/python3.12/site-packages/pymysql/cursors.py", line 153, in execute
    result = self._query(query)
             ^^^^^^^^^^^^^^^^^^
  File "/Users/mac/Library/Caches/pypoetry/virtualenvs/dummy-ueek8zWF-py3.12/lib/python3.12/site-packages/pymysql/cursors.py", line 322, in _query
    conn.query(q)
  File "/Users/mac/Library/Caches/pypoetry/virtualenvs/dummy-ueek8zWF-py3.12/lib/python3.12/site-packages/pymysql/connections.py", line 563, in query
    self._affected_rows = self._read_query_result(unbuffered=unbuffered)
                          ^^^^^^^^^^^^^^^^^^^^^^^^^^^^^^^^^^^^^^^^^^^^^^
  File "/Users/mac/Library/Caches/pypoetry/virtualenvs/dummy-ueek8zWF-py3.12/lib/python3.12/site-packages/pymysql/connections.py", line 825, in _read_query_result
    result.read()
  File "/Users/mac/Library/Caches/pypoetry/virtualenvs/dummy-ueek8zWF-py3.12/lib/python3.12/site-packages/pymysql/connections.py", line 1199, in read
    first_packet = self.connection._read_packet()
                   ^^^^^^^^^^^^^^^^^^^^^^^^^^^^^^
  File "/Users/mac/Library/Caches/pypoetry/virtualenvs/dummy-ueek8zWF-py3.12/lib/python3.12/site-packages/pymysql/connections.py", line 775, in _read_packet
    packet.raise_for_error()
  File "/Users/mac/Library/Caches/pypoetry/virtualenvs/dummy-ueek8zWF-py3.12/lib/python3.12/site-packages/pymysql/protocol.py", line 219, in raise_for_error
    err.raise_mysql_exception(self._data)
  File "/Users/mac/Library/Caches/pypoetry/virtualenvs/dummy-ueek8zWF-py3.12/lib/python3.12/site-packages/pymysql/err.py", line 150, in raise_mysql_exception
    raise errorclass(errno, errval)
pymysql.err.IntegrityError: (1062, "Duplicate entry 'kbrz' for key 'airport.icao_unq'")

The above exception was the direct cause of the following exception:

Traceback (most recent call last):
  File "/Users/mac/my_project/DummyGenerator/utils/insert_data.py", line 37, in insert_dummy_data
    conn.execute(query)
  File "/Users/mac/Library/Caches/pypoetry/virtualenvs/dummy-ueek8zWF-py3.12/lib/python3.12/site-packages/sqlalchemy/engine/base.py", line 1418, in execute
    return meth(
           ^^^^^
  File "/Users/mac/Library/Caches/pypoetry/virtualenvs/dummy-ueek8zWF-py3.12/lib/python3.12/site-packages/sqlalchemy/sql/elements.py", line 515, in _execute_on_connection
    return connection._execute_clauseelement(
           ^^^^^^^^^^^^^^^^^^^^^^^^^^^^^^^^^^
  File "/Users/mac/Library/Caches/pypoetry/virtualenvs/dummy-ueek8zWF-py3.12/lib/python3.12/site-packages/sqlalchemy/engine/base.py", line 1640, in _execute_clauseelement
    ret = self._execute_context(
          ^^^^^^^^^^^^^^^^^^^^^^
  File "/Users/mac/Library/Caches/pypoetry/virtualenvs/dummy-ueek8zWF-py3.12/lib/python3.12/site-packages/sqlalchemy/engine/base.py", line 1846, in _execute_context
    return self._exec_single_context(
           ^^^^^^^^^^^^^^^^^^^^^^^^^^
  File "/Users/mac/Library/Caches/pypoetry/virtualenvs/dummy-ueek8zWF-py3.12/lib/python3.12/site-packages/sqlalchemy/engine/base.py", line 1986, in _exec_single_context
    self._handle_dbapi_exception(
  File "/Users/mac/Library/Caches/pypoetry/virtualenvs/dummy-ueek8zWF-py3.12/lib/python3.12/site-packages/sqlalchemy/engine/base.py", line 2355, in _handle_dbapi_exception
    raise sqlalchemy_exception.with_traceback(exc_info[2]) from e
  File "/Users/mac/Library/Caches/pypoetry/virtualenvs/dummy-ueek8zWF-py3.12/lib/python3.12/site-packages/sqlalchemy/engine/base.py", line 1967, in _exec_single_context
    self.dialect.do_execute(
  File "/Users/mac/Library/Caches/pypoetry/virtualenvs/dummy-ueek8zWF-py3.12/lib/python3.12/site-packages/sqlalchemy/engine/default.py", line 941, in do_execute
    cursor.execute(statement, parameters)
  File "/Users/mac/Library/Caches/pypoetry/virtualenvs/dummy-ueek8zWF-py3.12/lib/python3.12/site-packages/pymysql/cursors.py", line 153, in execute
    result = self._query(query)
             ^^^^^^^^^^^^^^^^^^
  File "/Users/mac/Library/Caches/pypoetry/virtualenvs/dummy-ueek8zWF-py3.12/lib/python3.12/site-packages/pymysql/cursors.py", line 322, in _query
    conn.query(q)
  File "/Users/mac/Library/Caches/pypoetry/virtualenvs/dummy-ueek8zWF-py3.12/lib/python3.12/site-packages/pymysql/connections.py", line 563, in query
    self._affected_rows = self._read_query_result(unbuffered=unbuffered)
                          ^^^^^^^^^^^^^^^^^^^^^^^^^^^^^^^^^^^^^^^^^^^^^^
  File "/Users/mac/Library/Caches/pypoetry/virtualenvs/dummy-ueek8zWF-py3.12/lib/python3.12/site-packages/pymysql/connections.py", line 825, in _read_query_result
    result.read()
  File "/Users/mac/Library/Caches/pypoetry/virtualenvs/dummy-ueek8zWF-py3.12/lib/python3.12/site-packages/pymysql/connections.py", line 1199, in read
    first_packet = self.connection._read_packet()
                   ^^^^^^^^^^^^^^^^^^^^^^^^^^^^^^
  File "/Users/mac/Library/Caches/pypoetry/virtualenvs/dummy-ueek8zWF-py3.12/lib/python3.12/site-packages/pymysql/connections.py", line 775, in _read_packet
    packet.raise_for_error()
  File "/Users/mac/Library/Caches/pypoetry/virtualenvs/dummy-ueek8zWF-py3.12/lib/python3.12/site-packages/pymysql/protocol.py", line 219, in raise_for_error
    err.raise_mysql_exception(self._data)
  File "/Users/mac/Library/Caches/pypoetry/virtualenvs/dummy-ueek8zWF-py3.12/lib/python3.12/site-packages/pymysql/err.py", line 150, in raise_mysql_exception
    raise errorclass(errno, errval)
sqlalchemy.exc.IntegrityError: (pymysql.err.IntegrityError) (1062, "Duplicate entry 'kbrz' for key 'airport.icao_unq'")
[SQL: INSERT INTO airport (airport_id, iata, icao, name) VALUES (%(airport_id)s, %(iata)s, %(icao)s, %(name)s)]
[parameters: {'airport_id': None, 'iata': 'MTI', 'icao': 'kbrz', 'name': 'gDMKUgRYkAzmTiEFqjrMajVLXCAFdKSKnFryMVVKQLlYmThVxD'}]
(Background on this error at: https://sqlalche.me/e/20/gkpj)
2024-09-04 16:45:09,062 - ERROR - Failed to insert data into airport: (pymysql.err.IntegrityError) (1062, "Duplicate entry 'SNgf' for key 'airport.icao_unq'")
[SQL: INSERT INTO airport (airport_id, iata, icao, name) VALUES (%(airport_id)s, %(iata)s, %(icao)s, %(name)s)]
[parameters: {'airport_id': None, 'iata': 'UKf', 'icao': 'SNgf', 'name': 'moGypIfzzvDKFSNOrBHHUdjfkdirEsgmTXuEgClrVaRibzyqwM'}]
(Background on this error at: https://sqlalche.me/e/20/gkpj)
Traceback (most recent call last):
  File "/Users/mac/Library/Caches/pypoetry/virtualenvs/dummy-ueek8zWF-py3.12/lib/python3.12/site-packages/sqlalchemy/engine/base.py", line 1967, in _exec_single_context
    self.dialect.do_execute(
  File "/Users/mac/Library/Caches/pypoetry/virtualenvs/dummy-ueek8zWF-py3.12/lib/python3.12/site-packages/sqlalchemy/engine/default.py", line 941, in do_execute
    cursor.execute(statement, parameters)
  File "/Users/mac/Library/Caches/pypoetry/virtualenvs/dummy-ueek8zWF-py3.12/lib/python3.12/site-packages/pymysql/cursors.py", line 153, in execute
    result = self._query(query)
             ^^^^^^^^^^^^^^^^^^
  File "/Users/mac/Library/Caches/pypoetry/virtualenvs/dummy-ueek8zWF-py3.12/lib/python3.12/site-packages/pymysql/cursors.py", line 322, in _query
    conn.query(q)
  File "/Users/mac/Library/Caches/pypoetry/virtualenvs/dummy-ueek8zWF-py3.12/lib/python3.12/site-packages/pymysql/connections.py", line 563, in query
    self._affected_rows = self._read_query_result(unbuffered=unbuffered)
                          ^^^^^^^^^^^^^^^^^^^^^^^^^^^^^^^^^^^^^^^^^^^^^^
  File "/Users/mac/Library/Caches/pypoetry/virtualenvs/dummy-ueek8zWF-py3.12/lib/python3.12/site-packages/pymysql/connections.py", line 825, in _read_query_result
    result.read()
  File "/Users/mac/Library/Caches/pypoetry/virtualenvs/dummy-ueek8zWF-py3.12/lib/python3.12/site-packages/pymysql/connections.py", line 1199, in read
    first_packet = self.connection._read_packet()
                   ^^^^^^^^^^^^^^^^^^^^^^^^^^^^^^
  File "/Users/mac/Library/Caches/pypoetry/virtualenvs/dummy-ueek8zWF-py3.12/lib/python3.12/site-packages/pymysql/connections.py", line 775, in _read_packet
    packet.raise_for_error()
  File "/Users/mac/Library/Caches/pypoetry/virtualenvs/dummy-ueek8zWF-py3.12/lib/python3.12/site-packages/pymysql/protocol.py", line 219, in raise_for_error
    err.raise_mysql_exception(self._data)
  File "/Users/mac/Library/Caches/pypoetry/virtualenvs/dummy-ueek8zWF-py3.12/lib/python3.12/site-packages/pymysql/err.py", line 150, in raise_mysql_exception
    raise errorclass(errno, errval)
pymysql.err.IntegrityError: (1062, "Duplicate entry 'SNgf' for key 'airport.icao_unq'")

The above exception was the direct cause of the following exception:

Traceback (most recent call last):
  File "/Users/mac/my_project/DummyGenerator/utils/insert_data.py", line 37, in insert_dummy_data
    conn.execute(query)
  File "/Users/mac/Library/Caches/pypoetry/virtualenvs/dummy-ueek8zWF-py3.12/lib/python3.12/site-packages/sqlalchemy/engine/base.py", line 1418, in execute
    return meth(
           ^^^^^
  File "/Users/mac/Library/Caches/pypoetry/virtualenvs/dummy-ueek8zWF-py3.12/lib/python3.12/site-packages/sqlalchemy/sql/elements.py", line 515, in _execute_on_connection
    return connection._execute_clauseelement(
           ^^^^^^^^^^^^^^^^^^^^^^^^^^^^^^^^^^
  File "/Users/mac/Library/Caches/pypoetry/virtualenvs/dummy-ueek8zWF-py3.12/lib/python3.12/site-packages/sqlalchemy/engine/base.py", line 1640, in _execute_clauseelement
    ret = self._execute_context(
          ^^^^^^^^^^^^^^^^^^^^^^
  File "/Users/mac/Library/Caches/pypoetry/virtualenvs/dummy-ueek8zWF-py3.12/lib/python3.12/site-packages/sqlalchemy/engine/base.py", line 1846, in _execute_context
    return self._exec_single_context(
           ^^^^^^^^^^^^^^^^^^^^^^^^^^
  File "/Users/mac/Library/Caches/pypoetry/virtualenvs/dummy-ueek8zWF-py3.12/lib/python3.12/site-packages/sqlalchemy/engine/base.py", line 1986, in _exec_single_context
    self._handle_dbapi_exception(
  File "/Users/mac/Library/Caches/pypoetry/virtualenvs/dummy-ueek8zWF-py3.12/lib/python3.12/site-packages/sqlalchemy/engine/base.py", line 2355, in _handle_dbapi_exception
    raise sqlalchemy_exception.with_traceback(exc_info[2]) from e
  File "/Users/mac/Library/Caches/pypoetry/virtualenvs/dummy-ueek8zWF-py3.12/lib/python3.12/site-packages/sqlalchemy/engine/base.py", line 1967, in _exec_single_context
    self.dialect.do_execute(
  File "/Users/mac/Library/Caches/pypoetry/virtualenvs/dummy-ueek8zWF-py3.12/lib/python3.12/site-packages/sqlalchemy/engine/default.py", line 941, in do_execute
    cursor.execute(statement, parameters)
  File "/Users/mac/Library/Caches/pypoetry/virtualenvs/dummy-ueek8zWF-py3.12/lib/python3.12/site-packages/pymysql/cursors.py", line 153, in execute
    result = self._query(query)
             ^^^^^^^^^^^^^^^^^^
  File "/Users/mac/Library/Caches/pypoetry/virtualenvs/dummy-ueek8zWF-py3.12/lib/python3.12/site-packages/pymysql/cursors.py", line 322, in _query
    conn.query(q)
  File "/Users/mac/Library/Caches/pypoetry/virtualenvs/dummy-ueek8zWF-py3.12/lib/python3.12/site-packages/pymysql/connections.py", line 563, in query
    self._affected_rows = self._read_query_result(unbuffered=unbuffered)
                          ^^^^^^^^^^^^^^^^^^^^^^^^^^^^^^^^^^^^^^^^^^^^^^
  File "/Users/mac/Library/Caches/pypoetry/virtualenvs/dummy-ueek8zWF-py3.12/lib/python3.12/site-packages/pymysql/connections.py", line 825, in _read_query_result
    result.read()
  File "/Users/mac/Library/Caches/pypoetry/virtualenvs/dummy-ueek8zWF-py3.12/lib/python3.12/site-packages/pymysql/connections.py", line 1199, in read
    first_packet = self.connection._read_packet()
                   ^^^^^^^^^^^^^^^^^^^^^^^^^^^^^^
  File "/Users/mac/Library/Caches/pypoetry/virtualenvs/dummy-ueek8zWF-py3.12/lib/python3.12/site-packages/pymysql/connections.py", line 775, in _read_packet
    packet.raise_for_error()
  File "/Users/mac/Library/Caches/pypoetry/virtualenvs/dummy-ueek8zWF-py3.12/lib/python3.12/site-packages/pymysql/protocol.py", line 219, in raise_for_error
    err.raise_mysql_exception(self._data)
  File "/Users/mac/Library/Caches/pypoetry/virtualenvs/dummy-ueek8zWF-py3.12/lib/python3.12/site-packages/pymysql/err.py", line 150, in raise_mysql_exception
    raise errorclass(errno, errval)
sqlalchemy.exc.IntegrityError: (pymysql.err.IntegrityError) (1062, "Duplicate entry 'SNgf' for key 'airport.icao_unq'")
[SQL: INSERT INTO airport (airport_id, iata, icao, name) VALUES (%(airport_id)s, %(iata)s, %(icao)s, %(name)s)]
[parameters: {'airport_id': None, 'iata': 'UKf', 'icao': 'SNgf', 'name': 'moGypIfzzvDKFSNOrBHHUdjfkdirEsgmTXuEgClrVaRibzyqwM'}]
(Background on this error at: https://sqlalche.me/e/20/gkpj)
2024-09-04 16:55:32,806 - ERROR - Failed to insert data into airport: (pymysql.err.IntegrityError) (1062, "Duplicate entry 'asFN' for key 'airport.icao_unq'")
[SQL: INSERT INTO airport (airport_id, iata, icao, name) VALUES (%(airport_id)s, %(iata)s, %(icao)s, %(name)s)]
[parameters: {'airport_id': None, 'iata': 'zmy', 'icao': 'asFN', 'name': 'JirXEfJDvLYeiMnsPVVyDvVOKnupdXKZDsPToWXojtaKZhXchu'}]
(Background on this error at: https://sqlalche.me/e/20/gkpj)
Traceback (most recent call last):
  File "/Users/mac/Library/Caches/pypoetry/virtualenvs/dummy-ueek8zWF-py3.12/lib/python3.12/site-packages/sqlalchemy/engine/base.py", line 1967, in _exec_single_context
    self.dialect.do_execute(
  File "/Users/mac/Library/Caches/pypoetry/virtualenvs/dummy-ueek8zWF-py3.12/lib/python3.12/site-packages/sqlalchemy/engine/default.py", line 941, in do_execute
    cursor.execute(statement, parameters)
  File "/Users/mac/Library/Caches/pypoetry/virtualenvs/dummy-ueek8zWF-py3.12/lib/python3.12/site-packages/pymysql/cursors.py", line 153, in execute
    result = self._query(query)
             ^^^^^^^^^^^^^^^^^^
  File "/Users/mac/Library/Caches/pypoetry/virtualenvs/dummy-ueek8zWF-py3.12/lib/python3.12/site-packages/pymysql/cursors.py", line 322, in _query
    conn.query(q)
  File "/Users/mac/Library/Caches/pypoetry/virtualenvs/dummy-ueek8zWF-py3.12/lib/python3.12/site-packages/pymysql/connections.py", line 563, in query
    self._affected_rows = self._read_query_result(unbuffered=unbuffered)
                          ^^^^^^^^^^^^^^^^^^^^^^^^^^^^^^^^^^^^^^^^^^^^^^
  File "/Users/mac/Library/Caches/pypoetry/virtualenvs/dummy-ueek8zWF-py3.12/lib/python3.12/site-packages/pymysql/connections.py", line 825, in _read_query_result
    result.read()
  File "/Users/mac/Library/Caches/pypoetry/virtualenvs/dummy-ueek8zWF-py3.12/lib/python3.12/site-packages/pymysql/connections.py", line 1199, in read
    first_packet = self.connection._read_packet()
                   ^^^^^^^^^^^^^^^^^^^^^^^^^^^^^^
  File "/Users/mac/Library/Caches/pypoetry/virtualenvs/dummy-ueek8zWF-py3.12/lib/python3.12/site-packages/pymysql/connections.py", line 775, in _read_packet
    packet.raise_for_error()
  File "/Users/mac/Library/Caches/pypoetry/virtualenvs/dummy-ueek8zWF-py3.12/lib/python3.12/site-packages/pymysql/protocol.py", line 219, in raise_for_error
    err.raise_mysql_exception(self._data)
  File "/Users/mac/Library/Caches/pypoetry/virtualenvs/dummy-ueek8zWF-py3.12/lib/python3.12/site-packages/pymysql/err.py", line 150, in raise_mysql_exception
    raise errorclass(errno, errval)
pymysql.err.IntegrityError: (1062, "Duplicate entry 'asFN' for key 'airport.icao_unq'")

The above exception was the direct cause of the following exception:

Traceback (most recent call last):
  File "/Users/mac/my_project/DummyGenerator/utils/insert_data.py", line 37, in insert_dummy_data
    conn.execute(query)
  File "/Users/mac/Library/Caches/pypoetry/virtualenvs/dummy-ueek8zWF-py3.12/lib/python3.12/site-packages/sqlalchemy/engine/base.py", line 1418, in execute
    return meth(
           ^^^^^
  File "/Users/mac/Library/Caches/pypoetry/virtualenvs/dummy-ueek8zWF-py3.12/lib/python3.12/site-packages/sqlalchemy/sql/elements.py", line 515, in _execute_on_connection
    return connection._execute_clauseelement(
           ^^^^^^^^^^^^^^^^^^^^^^^^^^^^^^^^^^
  File "/Users/mac/Library/Caches/pypoetry/virtualenvs/dummy-ueek8zWF-py3.12/lib/python3.12/site-packages/sqlalchemy/engine/base.py", line 1640, in _execute_clauseelement
    ret = self._execute_context(
          ^^^^^^^^^^^^^^^^^^^^^^
  File "/Users/mac/Library/Caches/pypoetry/virtualenvs/dummy-ueek8zWF-py3.12/lib/python3.12/site-packages/sqlalchemy/engine/base.py", line 1846, in _execute_context
    return self._exec_single_context(
           ^^^^^^^^^^^^^^^^^^^^^^^^^^
  File "/Users/mac/Library/Caches/pypoetry/virtualenvs/dummy-ueek8zWF-py3.12/lib/python3.12/site-packages/sqlalchemy/engine/base.py", line 1986, in _exec_single_context
    self._handle_dbapi_exception(
  File "/Users/mac/Library/Caches/pypoetry/virtualenvs/dummy-ueek8zWF-py3.12/lib/python3.12/site-packages/sqlalchemy/engine/base.py", line 2355, in _handle_dbapi_exception
    raise sqlalchemy_exception.with_traceback(exc_info[2]) from e
  File "/Users/mac/Library/Caches/pypoetry/virtualenvs/dummy-ueek8zWF-py3.12/lib/python3.12/site-packages/sqlalchemy/engine/base.py", line 1967, in _exec_single_context
    self.dialect.do_execute(
  File "/Users/mac/Library/Caches/pypoetry/virtualenvs/dummy-ueek8zWF-py3.12/lib/python3.12/site-packages/sqlalchemy/engine/default.py", line 941, in do_execute
    cursor.execute(statement, parameters)
  File "/Users/mac/Library/Caches/pypoetry/virtualenvs/dummy-ueek8zWF-py3.12/lib/python3.12/site-packages/pymysql/cursors.py", line 153, in execute
    result = self._query(query)
             ^^^^^^^^^^^^^^^^^^
  File "/Users/mac/Library/Caches/pypoetry/virtualenvs/dummy-ueek8zWF-py3.12/lib/python3.12/site-packages/pymysql/cursors.py", line 322, in _query
    conn.query(q)
  File "/Users/mac/Library/Caches/pypoetry/virtualenvs/dummy-ueek8zWF-py3.12/lib/python3.12/site-packages/pymysql/connections.py", line 563, in query
    self._affected_rows = self._read_query_result(unbuffered=unbuffered)
                          ^^^^^^^^^^^^^^^^^^^^^^^^^^^^^^^^^^^^^^^^^^^^^^
  File "/Users/mac/Library/Caches/pypoetry/virtualenvs/dummy-ueek8zWF-py3.12/lib/python3.12/site-packages/pymysql/connections.py", line 825, in _read_query_result
    result.read()
  File "/Users/mac/Library/Caches/pypoetry/virtualenvs/dummy-ueek8zWF-py3.12/lib/python3.12/site-packages/pymysql/connections.py", line 1199, in read
    first_packet = self.connection._read_packet()
                   ^^^^^^^^^^^^^^^^^^^^^^^^^^^^^^
  File "/Users/mac/Library/Caches/pypoetry/virtualenvs/dummy-ueek8zWF-py3.12/lib/python3.12/site-packages/pymysql/connections.py", line 775, in _read_packet
    packet.raise_for_error()
  File "/Users/mac/Library/Caches/pypoetry/virtualenvs/dummy-ueek8zWF-py3.12/lib/python3.12/site-packages/pymysql/protocol.py", line 219, in raise_for_error
    err.raise_mysql_exception(self._data)
  File "/Users/mac/Library/Caches/pypoetry/virtualenvs/dummy-ueek8zWF-py3.12/lib/python3.12/site-packages/pymysql/err.py", line 150, in raise_mysql_exception
    raise errorclass(errno, errval)
sqlalchemy.exc.IntegrityError: (pymysql.err.IntegrityError) (1062, "Duplicate entry 'asFN' for key 'airport.icao_unq'")
[SQL: INSERT INTO airport (airport_id, iata, icao, name) VALUES (%(airport_id)s, %(iata)s, %(icao)s, %(name)s)]
[parameters: {'airport_id': None, 'iata': 'zmy', 'icao': 'asFN', 'name': 'JirXEfJDvLYeiMnsPVVyDvVOKnupdXKZDsPToWXojtaKZhXchu'}]
(Background on this error at: https://sqlalche.me/e/20/gkpj)
2024-09-04 16:55:32,819 - ERROR - Failed to insert data into airport: (pymysql.err.IntegrityError) (1062, "Duplicate entry 'oPRs' for key 'airport.icao_unq'")
[SQL: INSERT INTO airport (airport_id, iata, icao, name) VALUES (%(airport_id)s, %(iata)s, %(icao)s, %(name)s)]
[parameters: {'airport_id': None, 'iata': 'Jgw', 'icao': 'oPRs', 'name': 'qcKTigBHKBMZpPgajTLsdqwxdEOwQYKNDdQjcBFVuqSTUiLiif'}]
(Background on this error at: https://sqlalche.me/e/20/gkpj)
Traceback (most recent call last):
  File "/Users/mac/Library/Caches/pypoetry/virtualenvs/dummy-ueek8zWF-py3.12/lib/python3.12/site-packages/sqlalchemy/engine/base.py", line 1967, in _exec_single_context
    self.dialect.do_execute(
  File "/Users/mac/Library/Caches/pypoetry/virtualenvs/dummy-ueek8zWF-py3.12/lib/python3.12/site-packages/sqlalchemy/engine/default.py", line 941, in do_execute
    cursor.execute(statement, parameters)
  File "/Users/mac/Library/Caches/pypoetry/virtualenvs/dummy-ueek8zWF-py3.12/lib/python3.12/site-packages/pymysql/cursors.py", line 153, in execute
    result = self._query(query)
             ^^^^^^^^^^^^^^^^^^
  File "/Users/mac/Library/Caches/pypoetry/virtualenvs/dummy-ueek8zWF-py3.12/lib/python3.12/site-packages/pymysql/cursors.py", line 322, in _query
    conn.query(q)
  File "/Users/mac/Library/Caches/pypoetry/virtualenvs/dummy-ueek8zWF-py3.12/lib/python3.12/site-packages/pymysql/connections.py", line 563, in query
    self._affected_rows = self._read_query_result(unbuffered=unbuffered)
                          ^^^^^^^^^^^^^^^^^^^^^^^^^^^^^^^^^^^^^^^^^^^^^^
  File "/Users/mac/Library/Caches/pypoetry/virtualenvs/dummy-ueek8zWF-py3.12/lib/python3.12/site-packages/pymysql/connections.py", line 825, in _read_query_result
    result.read()
  File "/Users/mac/Library/Caches/pypoetry/virtualenvs/dummy-ueek8zWF-py3.12/lib/python3.12/site-packages/pymysql/connections.py", line 1199, in read
    first_packet = self.connection._read_packet()
                   ^^^^^^^^^^^^^^^^^^^^^^^^^^^^^^
  File "/Users/mac/Library/Caches/pypoetry/virtualenvs/dummy-ueek8zWF-py3.12/lib/python3.12/site-packages/pymysql/connections.py", line 775, in _read_packet
    packet.raise_for_error()
  File "/Users/mac/Library/Caches/pypoetry/virtualenvs/dummy-ueek8zWF-py3.12/lib/python3.12/site-packages/pymysql/protocol.py", line 219, in raise_for_error
    err.raise_mysql_exception(self._data)
  File "/Users/mac/Library/Caches/pypoetry/virtualenvs/dummy-ueek8zWF-py3.12/lib/python3.12/site-packages/pymysql/err.py", line 150, in raise_mysql_exception
    raise errorclass(errno, errval)
pymysql.err.IntegrityError: (1062, "Duplicate entry 'oPRs' for key 'airport.icao_unq'")

The above exception was the direct cause of the following exception:

Traceback (most recent call last):
  File "/Users/mac/my_project/DummyGenerator/utils/insert_data.py", line 37, in insert_dummy_data
    conn.execute(query)
  File "/Users/mac/Library/Caches/pypoetry/virtualenvs/dummy-ueek8zWF-py3.12/lib/python3.12/site-packages/sqlalchemy/engine/base.py", line 1418, in execute
    return meth(
           ^^^^^
  File "/Users/mac/Library/Caches/pypoetry/virtualenvs/dummy-ueek8zWF-py3.12/lib/python3.12/site-packages/sqlalchemy/sql/elements.py", line 515, in _execute_on_connection
    return connection._execute_clauseelement(
           ^^^^^^^^^^^^^^^^^^^^^^^^^^^^^^^^^^
  File "/Users/mac/Library/Caches/pypoetry/virtualenvs/dummy-ueek8zWF-py3.12/lib/python3.12/site-packages/sqlalchemy/engine/base.py", line 1640, in _execute_clauseelement
    ret = self._execute_context(
          ^^^^^^^^^^^^^^^^^^^^^^
  File "/Users/mac/Library/Caches/pypoetry/virtualenvs/dummy-ueek8zWF-py3.12/lib/python3.12/site-packages/sqlalchemy/engine/base.py", line 1846, in _execute_context
    return self._exec_single_context(
           ^^^^^^^^^^^^^^^^^^^^^^^^^^
  File "/Users/mac/Library/Caches/pypoetry/virtualenvs/dummy-ueek8zWF-py3.12/lib/python3.12/site-packages/sqlalchemy/engine/base.py", line 1986, in _exec_single_context
    self._handle_dbapi_exception(
  File "/Users/mac/Library/Caches/pypoetry/virtualenvs/dummy-ueek8zWF-py3.12/lib/python3.12/site-packages/sqlalchemy/engine/base.py", line 2355, in _handle_dbapi_exception
    raise sqlalchemy_exception.with_traceback(exc_info[2]) from e
  File "/Users/mac/Library/Caches/pypoetry/virtualenvs/dummy-ueek8zWF-py3.12/lib/python3.12/site-packages/sqlalchemy/engine/base.py", line 1967, in _exec_single_context
    self.dialect.do_execute(
  File "/Users/mac/Library/Caches/pypoetry/virtualenvs/dummy-ueek8zWF-py3.12/lib/python3.12/site-packages/sqlalchemy/engine/default.py", line 941, in do_execute
    cursor.execute(statement, parameters)
  File "/Users/mac/Library/Caches/pypoetry/virtualenvs/dummy-ueek8zWF-py3.12/lib/python3.12/site-packages/pymysql/cursors.py", line 153, in execute
    result = self._query(query)
             ^^^^^^^^^^^^^^^^^^
  File "/Users/mac/Library/Caches/pypoetry/virtualenvs/dummy-ueek8zWF-py3.12/lib/python3.12/site-packages/pymysql/cursors.py", line 322, in _query
    conn.query(q)
  File "/Users/mac/Library/Caches/pypoetry/virtualenvs/dummy-ueek8zWF-py3.12/lib/python3.12/site-packages/pymysql/connections.py", line 563, in query
    self._affected_rows = self._read_query_result(unbuffered=unbuffered)
                          ^^^^^^^^^^^^^^^^^^^^^^^^^^^^^^^^^^^^^^^^^^^^^^
  File "/Users/mac/Library/Caches/pypoetry/virtualenvs/dummy-ueek8zWF-py3.12/lib/python3.12/site-packages/pymysql/connections.py", line 825, in _read_query_result
    result.read()
  File "/Users/mac/Library/Caches/pypoetry/virtualenvs/dummy-ueek8zWF-py3.12/lib/python3.12/site-packages/pymysql/connections.py", line 1199, in read
    first_packet = self.connection._read_packet()
                   ^^^^^^^^^^^^^^^^^^^^^^^^^^^^^^
  File "/Users/mac/Library/Caches/pypoetry/virtualenvs/dummy-ueek8zWF-py3.12/lib/python3.12/site-packages/pymysql/connections.py", line 775, in _read_packet
    packet.raise_for_error()
  File "/Users/mac/Library/Caches/pypoetry/virtualenvs/dummy-ueek8zWF-py3.12/lib/python3.12/site-packages/pymysql/protocol.py", line 219, in raise_for_error
    err.raise_mysql_exception(self._data)
  File "/Users/mac/Library/Caches/pypoetry/virtualenvs/dummy-ueek8zWF-py3.12/lib/python3.12/site-packages/pymysql/err.py", line 150, in raise_mysql_exception
    raise errorclass(errno, errval)
sqlalchemy.exc.IntegrityError: (pymysql.err.IntegrityError) (1062, "Duplicate entry 'oPRs' for key 'airport.icao_unq'")
[SQL: INSERT INTO airport (airport_id, iata, icao, name) VALUES (%(airport_id)s, %(iata)s, %(icao)s, %(name)s)]
[parameters: {'airport_id': None, 'iata': 'Jgw', 'icao': 'oPRs', 'name': 'qcKTigBHKBMZpPgajTLsdqwxdEOwQYKNDdQjcBFVuqSTUiLiif'}]
(Background on this error at: https://sqlalche.me/e/20/gkpj)
